<?xml version="1.0" ?>
<robot name="valve_handle">
	<link name="base_link" />

	<link name="valve">
		<inertial>
			<origin xyz="0 0 0" rpy="0 0 0" />
			<mass value="1."/>
			<inertia ixx="1" ixy="0" ixz="0"
			iyy="1" iyz="0"
			izz="1" />
		</inertial>
		<visual>
			<geometry>
				<mesh filename="package://mc_int_obj_description/meshes/valve/valve.stl" />
			</geometry>
				<material name="Material">
				<color rgba="1.0 0.0 0.0 1" />
			</material>
		</visual>
	</link>

	<joint name="valve" type="continuous">
		<axis xyz="1 0 0"/>
		<limit effort="0" velocity="100" />
		<parent link="base_link" />
		<child link="valve" />
		<origin rpy="0.0 0.0 0.0" xyz="0.0 0.0 0.0" />
	</joint>

	<link name="handle">
		<inertial>
			<origin xyz="0 0 0" rpy="0 0 0" />
			<mass value="0.1"/>
			<inertia ixx="1" ixy="0" ixz="0"
			iyy="1" iyz="0"
			izz="1" />
		</inertial>
		<visual>
			<geometry>
				<mesh filename="package://mc_int_obj_description/meshes/valve_handle/handle.stl" />
			</geometry>
			<material name="Material">
				<color rgba="1.0 0.0 0.0 1" />
			</material>
		</visual>

	</link>
		<joint name="handle" type="continuous">
		<axis xyz="0 0 1"/>
		<limit effort="0" velocity="100" />
		<parent link="valve" />
		<child link="handle" />
		<origin rpy="0.0 1.5707969665527344 0.0" xyz="0.0939900279045105 0.0 0.20249678194522858" />
	</joint>
</robot>
